gen-ERROR:未捕获异常
Traceback (most recent call last):
  File "<frozen runpy>", line 198, in _run_module_as_main
  File "<frozen runpy>", line 88, in _run_code
  File "D:\Applications\Scoop\apps\python\current\Scripts\ee.exe\__main__.py", line 4, in <module>
    from excelexporter.__main__ import main
  File "D:\Applications\Scoop\apps\python\current\Lib\site-packages\excelexporter\__main__.py", line 3, in <module>
    main()
  File "D:\Applications\Scoop\apps\python\current\Lib\site-packages\click\core.py", line 1130, in __call__
    return self.main(*args, **kwargs)
           ^^^^^^^^^^^^^^^^^^^^^^^^^^
  File "D:\Applications\Scoop\apps\python\current\Lib\site-packages\click\core.py", line 1055, in main
    rv = self.invoke(ctx)
         ^^^^^^^^^^^^^^^^
  File "D:\Applications\Scoop\apps\python\current\Lib\site-packages\click\core.py", line 1657, in invoke
    return _process_result(sub_ctx.command.invoke(sub_ctx))
                           ^^^^^^^^^^^^^^^^^^^^^^^^^^^^^^^
  File "D:\Applications\Scoop\apps\python\current\Lib\site-packages\click\core.py", line 1404, in invoke
    return ctx.invoke(self.callback, **ctx.params)
           ^^^^^^^^^^^^^^^^^^^^^^^^^^^^^^^^^^^^^^^
  File "D:\Applications\Scoop\apps\python\current\Lib\site-packages\click\core.py", line 760, in invoke
    return __callback(*args, **kwargs)
           ^^^^^^^^^^^^^^^^^^^^^^^^^^^
  File "D:\Applications\Scoop\apps\python\current\Lib\site-packages\excelexporter\cli.py", line 99, in init
    os.mkdir(exporter.CFG["settings"]["input"])
FileExistsError: [WinError 183] 当文件已存在时，无法创建该文件。: 'data'
